Workbook

Sheet 표지
A5: ="1. 성별 이동자 수 및 이동률 추이, 1970-"&G5 -> 1. 성별 이동자 수 및 이동률 추이, 1970-2025 | F5: 작업년도 | G5: 2025
A7: ="2. 성․연령별 이동자 수 및 이동률 추이, "&G5-20&"-"&G5 -> 2. 성․연령별 이동자 수 및 이동률 추이, 2005-2025
A9: ="3. 시도별 이동자 수 추이, "&G5-20&"-"&G5 -> 3. 시도별 이동자 수 추이, 2005-2025
A11: ="4. 시도․성별 이동자 수 및 이동률, "&G5 -> 4. 시도․성별 이동자 수 및 이동률, 2025
A13: ="5. 시도 및 성․연령별 순이동자 수, "&G5 -> 5. 시도 및 성․연령별 순이동자 수, 2025
A15: ="6. 시도 전입․전출지 및 성별 이동자 수, "&G5 -> 6. 시도 전입․전출지 및 성별 이동자 수, 2025
A17: ="7. 시도 전입․전출지 및 성별 순이동자 수, "&G5 -> 7. 시도 전입․전출지 및 성별 순이동자 수, 2025
A19: ="8. 수도권 이동자 수 추이, 1990-"&G5 -> 8. 수도권 이동자 수 추이, 1990-2025
A21: ="9. 월별 인구이동 추이, "&G5-2&"-"&G5 -> 9. 월별 인구이동 추이, 2023-2025
A23: ="10. 시도 및 전입사유별 이동자 수, "&G5 -> 10. 시도 및 전입사유별 이동자 수, 2025
A25: ="※ 참고표: 이동건 수(전입신고건 수) 추이, "&G5-20&"-"&G5 -> ※ 참고표: 이동건 수(전입신고건 수) 추이, 2005-2025

Sheet 1. 성별 이동자수 및 이동률 추이
A1: ="1.성별 이동자 수 및 이동률 추이, 1970-"&표지!G5 -> 1.성별 이동자 수 및 이동률 추이, 1970-2025
Q2: (단위: 명, %, 여자 1백명당 남자)
A3: 연도 | B3: 총이동 | H3: 총이동 | M3: 시도내 | O3: 시도간 | Q3: 연도
B4: 이동자수 | H4: 이동률 | M4: 이동자수 | N4: 이동률 | O4: 이동자수 | P4: 이동률
B5: 남녀전체 | C5: 증감 | D5: 증감률 | E5: 남자 | F5: 여자 | G5: 성비 | H5: 남녀전체 | I5: 증감 | J5: 남자 | K5: 여자 | L5: 성비 | M5: 남녀전체 | N5: 남녀전체 | O5: 남녀전체 | P5: 남녀전체
A7: 1970 | B7: 4 046 536 | C7: - | D7: - | E7: 2 150 793 | F7: 1 895 743 | G7: 113.5 | H7: 12.6 | I7: - | J7: 13.2 | K7: 11.9 | L7: 110.8 | M7: 2 780 068 | N7: 8.6 | O7: 1 266 468 | P7: 3.9 | Q7: 1970
A8: 1971 | B8: 4 210 164 | C8: 163 628 | D8: 4 | E8: 2 188 457 | F8: 2 021 707 | G8: 108.2 | H8: 12.8 | I8: 0.3 | J8: 13.1 | K8: 12.5 | L8: 105.5 | M8: 2 878 091 | N8: 8.8 | O8: 1 332 073 | P8: 4.1 | Q8: 1971
A9: 1972 | B9: 3 687 938 | C9: -522226 | D9: -12.4 | E9: 1 933 929 | F9: 1 754 009 | G9: 110.3 | H9: 11 | I9: -1.8 | J9: 11.4 | K9: 10.6 | L9: 107.6 | M9: 2 619 367 | N9: 7.8 | O9: 1 068 571 | P9: 3.2 | Q9: 1972
A10: 1973 | B10: 4 860 418 | C10: 1 172 480 | D10: 31.8 | E10: 2 525 389 | F10: 2 335 029 | G10: 108.2 | H10: 14.3 | I10: 3.2 | J10: 14.7 | K10: 13.8 | L10: 105.9 | M10: 3 435 573 | N10: 10.1 | O10: 1 424 845 | P10: 4.2 | Q10: 1973
A11: 1974 | B11: 5 297 969 | C11: 437 551 | D11: 9 | E11: 2 752 074 | F11: 2 545 895 | G11: 108.1 | H11: 15.3 | I11: 1 | J11: 15.7 | K11: 14.8 | L11: 106 | M11: 3 709 343 | N11: 10.7 | O11: 1 588 626 | P11: 4.6 | Q11: 1974
A12: 1975 | B12: 9 011 440 | C12: 3 713 471 | D12: 70.1 | E12: 4 505 871 | F12: 4 505 569 | G12: 100 | H12: 25.5 | I12: 10.3 | J12: 25.4 | K12: 25.7 | L12: 98.6 | M12: 6 143 486 | N12: 17.4 | O12: 2 867 954 | P12: 8.1 | Q12: 1975
A13: 1976 | B13: 6 773 250 | C13: -2238190 | D13: -24.8 | E13: 3 576 261 | F13: 3 196 989 | G13: 111.9 | H13: 18.9 | I13: -6.6 | J13: 19.8 | K13: 18 | L13: 110.2 | M13: 4 620 297 | N13: 12.9 | O13: 2 152 953 | P13: 6 | Q13: 1976
A14: 1977 | B14: 7 397 623 | C14: 624 373 | D14: 9.2 | E14: 3 912 894 | F14: 3 484 729 | G14: 112.3 | H14: 20.3 | I14: 1.4 | J14: 21.3 | K14: 19.3 | L14: 110.5 | M14: 5 234 058 | N14: 14.4 | O14: 2 163 565 | P14: 5.9 | Q14: 1977
A15: 1978 | B15: 8 410 276 | C15: 1 012 653 | D15: 13.7 | E15: 4 388 655 | F15: 4 021 621 | G15: 109.1 | H15: 22.7 | I15: 2.4 | J15: 23.5 | K15: 21.9 | L15: 107.3 | M15: 5 867 479 | N15: 15.9 | O15: 2 542 797 | P15: 6.9 | Q15: 1978
A16: 1979 | B16: 7 324 380 | C16: -1085896 | D16: -12.9 | E16: 3 904 662 | F16: 3 419 718 | G16: 114.2 | H16: 19.5 | I16: -3.2 | J16: 20.6 | K16: 18.4 | L16: 112.2 | M16: 4 974 831 | N16: 13.3 | O16: 2 349 549 | P16: 6.3 | Q16: 1979
A17: 1980 | B17: 8 258 573 | C17: 934 193 | D17: 12.8 | E17: 4 275 107 | F17: 3 983 466 | G17: 107.3 | H17: 21.7 | I17: 2.1 | J17: 22.2 | K17: 21.1 | L17: 105.4 | M17: 5 652 936 | N17: 14.8 | O17: 2 605 637 | P17: 6.8 | Q17: 1980
A18: 1981 | B18: 8 194 516 | C18: -64057 | D18: -0.8 | E18: 4 222 102 | F18: 3 972 414 | G18: 106.3 | H18: 21.2 | I18: -0.5 | J18: 21.6 | K18: 20.7 | L18: 104.4 | M18: 5 401 067 | N18: 13.9 | O18: 2 793 449 | P18: 7.2 | Q18: 1981
A19: 1982 | B19: 8 616 474 | C19: 421 958 | D19: 5.1 | E19: 4 446 382 | F19: 4 170 092 | G19: 106.6 | H19: 21.9 | I19: 0.7 | J19: 22.4 | K19: 21.4 | L19: 104.8 | M19: 5 806 253 | N19: 14.8 | O19: 2 810 221 | P19: 7.1 | Q19: 1982
A20: 1983 | B20: 9 795 811 | C20: 1 179 337 | D20: 13.7 | E20: 4 983 047 | F20: 4 812 764 | G20: 103.5 | H20: 24.5 | I20: 2.6 | J20: 24.8 | K20: 24.3 | L20: 101.7 | M20: 6 584 773 | N20: 16.5 | O20: 3 211 038 | P20: 8 | Q20: 1983
A21: 1984 | B21: 9 043 238 | C21: -752573 | D21: -7.7 | E21: 4 633 161 | F21: 4 410 077 | G21: 105.1 | H21: 22.4 | I21: -2.2 | J21: 22.7 | K21: 22 | L21: 103.3 | M21: 6 033 834 | N21: 14.9 | O21: 3 009 404 | P21: 7.4 | Q21: 1984
A22: 1985 | B22: 8 679 097 | C22: -364141 | D22: -4 | E22: 4 439 543 | F22: 4 239 554 | G22: 104.7 | H22: 21.3 | I22: -1.1 | J22: 21.6 | K22: 21 | L22: 103 | M22: 5 753 800 | N22: 14.1 | O22: 2 925 297 | P22: 7.2 | Q22: 1985
A23: 1986 | B23: 8 660 428 | C23: -18669 | D23: -0.2 | E23: 4 430 249 | F23: 4 230 179 | G23: 104.7 | H23: 21 | I23: -0.3 | J23: 21.3 | K23: 20.7 | L23: 103.1 | M23: 5 639 139 | N23: 13.7 | O23: 3 021 289 | P23: 7.3 | Q23: 1986
A24: 1987 | B24: 9 308 750 | C24: 648 322 | D24: 7.5 | E24: 4 724 129 | F24: 4 584 621 | G24: 103 | H24: 22.4 | I24: 1.4 | J24: 22.5 | K24: 22.2 | L24: 101.6 | M24: 6 065 385 | N24: 14.6 | O24: 3 243 365 | P24: 7.8 | Q24: 1987
A25: 1988 | B25: 9 969 020 | C25: 660 270 | D25: 7.1 | E25: 5 059 833 | F25: 4 909 187 | G25: 103.1 | H25: 23.7 | I25: 1.4 | J25: 23.9 | K25: 23.5 | L25: 101.7 | M25: 6 616 530 | N25: 15.7 | O25: 3 352 490 | P25: 8 | Q25: 1988
A26: 1989 | B26: 9 316 219 | C26: -652801 | D26: -6.5 | E26: 4 719 029 | F26: 4 597 190 | G26: 102.7 | H26: 21.9 | I26: -1.8 | J26: 22.1 | K26: 21.8 | L26: 101.4 | M26: 6 126 613 | N26: 14.4 | O26: 3 189 606 | P26: 7.5 | Q26: 1989
A27: 1990 | B27: 9 459 209 | C27: 142 990 | D27: 1.5 | E27: 4 807 320 | F27: 4 651 889 | G27: 103.3 | H27: 22.1 | I27: 0.1 | J27: 22.3 | K27: 21.8 | L27: 102.1 | M27: 6 228 081 | N27: 14.5 | O27: 3 231 128 | P27: 7.5 | Q27: 1990
A28: 1991 | B28: 8 980 841 | C28: -478368 | D28: -5.1 | E28: 4 541 696 | F28: 4 439 145 | G28: 102.3 | H28: 20.7 | I28: -1.3 | J28: 20.8 | K28: 20.6 | L28: 101 | M28: 6 022 999 | N28: 13.9 | O28: 2 957 842 | P28: 6.8 | Q28: 1991
A29: 1992 | B29: 9 031 576 | C29: 50 735 | D29: 0.6 | E29: 4 542 387 | F29: 4 489 189 | G29: 101.2 | H29: 20.6 | I29: -0.1 | J29: 20.6 | K29: 20.7 | L29: 99.9 | M29: 6 171 816 | N29: 14.1 | O29: 2 859 760 | P29: 6.5 | Q29: 1992
A30: 1993 | B30: 8 807 058 | C30: -224518 | D30: -2.5 | E30: 4 430 204 | F30: 4 376 854 | G30: 101.2 | H30: 19.7 | I30: -1 | J30: 19.7 | K30: 19.6 | L30: 100.3 | M30: 5 943 391 | N30: 13.3 | O30: 2 863 667 | P30: 6.4 | Q30: 1993
A31: 1994 | B31: 8 791 714 | C31: -15344 | D31: -0.2 | E31: 4 406 649 | F31: 4 385 065 | G31: 100.5 | H31: 19.4 | I31: -0.2 | J31: 19.4 | K31: 19.5 | L31: 99.6 | M31: 6 052 025 | N31: 13.4 | O31: 2 739 689 | P31: 6.1 | Q31: 1994
A32: 1995 | B32: 9 073 069 | C32: 281 355 | D32: 3.2 | E32: 4 538 295 | F32: 4 534 774 | G32: 100.1 | H32: 19.9 | I32: 0.4 | J32: 19.8 | K32: 20 | L32: 99.1 | M32: 6 208 130 | N32: 13.6 | O32: 2 864 939 | P32: 6.3 | Q32: 1995
A33: 1996 | B33: 8 854 973 | C33: -218096 | D33: -2.4 | E33: 4 429 999 | F33: 4 424 974 | G33: 100.1 | H33: 19.2 | I33: -0.7 | J33: 19.1 | K33: 19.3 | L33: 99.2 | M33: 6 018 884 | N33: 13.1 | O33: 2 836 089 | P33: 6.2 | Q33: 1996
A34: 1997 | B34: 8 819 909 | C34: -35064 | D34: -0.4 | E34: 4 409 734 | F34: 4 410 175 | G34: 100 | H34: 19 | I34: -0.2 | J34: 18.9 | K34: 19.1 | L34: 99.1 | M34: 5 981 467 | N34: 12.9 | O34: 2 838 442 | P34: 6.1 | Q34: 1997
A35: 1998 | B35: 8 156 318 | C35: -663591 | D35: -7.5 | E35: 4 053 354 | F35: 4 102 964 | G35: 98.8 | H35: 17.4 | I35: -1.6 | J35: 17.2 | K35: 17.6 | L35: 97.9 | M35: 5 477 689 | N35: 11.7 | O35: 2 678 629 | P35: 5.7 | Q35: 1998
A36: 1999 | B36: 9 435 347 | C36: 1 279 029 | D36: 15.7 | E36: 4 640 988 | F36: 4 794 359 | G36: 96.8 | H36: 20 | I36: 2.6 | J36: 19.6 | K36: 20.4 | L36: 96 | M36: 6 410 563 | N36: 13.6 | O36: 3 024 784 | P36: 6.4 | Q36: 1999
A37: 2000 | B37: 9 009 441 | C37: -425906 | D37: -4.5 | E37: 4 474 676 | F37: 4 534 765 | G37: 98.7 | H37: 19 | I37: -1.1 | J37: 18.8 | K37: 19.2 | L37: 97.9 | M37: 6 163 610 | N37: 13 | O37: 2 845 831 | P37: 6 | Q37: 2000
A38: 2001 | B38: 9 289 949 | C38: 280 508 | D38: 3.1 | E38: 4 617 565 | F38: 4 672 384 | G38: 98.8 | H38: 19.4 | I38: 0.5 | J38: 19.2 | K38: 19.6 | L38: 98.1 | M38: 6 357 932 | N38: 13.3 | O38: 2 932 017 | P38: 6.1 | Q38: 2001
A39: 2002 | B39: 9 584 461 | C39: 294 512 | D39: 3.2 | E39: 4 755 557 | F39: 4 828 904 | G39: 98.5 | H39: 19.9 | I39: 0.5 | J39: 19.7 | K39: 20.1 | L39: 97.8 | M39: 6 589 646 | N39: 13.7 | O39: 2 994 815 | P39: 6.2 | Q39: 2002
A40: 2003 | B40: 9 516 605 | C40: -67856 | D40: -0.7 | E40: 4 704 601 | F40: 4 812 004 | G40: 97.8 | H40: 19.7 | I40: -0.2 | J40: 19.4 | K40: 20 | L40: 97.1 | M40: 6 508 824 | N40: 13.5 | O40: 3 007 781 | P40: 6.2 | Q40: 2003
A41: 2004 | B41: 8 567 795 | C41: -948810 | D41: -10 | E41: 4 267 695 | F41: 4 300 100 | G41: 99.2 | H41: 17.7 | I41: -2 | J41: 17.6 | K41: 17.8 | L41: 98.6 | M41: 5 774 056 | N41: 11.9 | O41: 2 793 739 | P41: 5.8 | Q41: 2004
...

Sheet 2. 성 및 연령별 이동자수 및 이동률추이
A1: ="2. 성·연령별 이동자 수 및 이동률 추이, "&LEFT(C3,4)&"-"&LEFT(AQ3,4) -> 2. 성·연령별 이동자 수 및 이동률 추이, 2005-2025
AT2: (단위: 천 명, %)
A3: 성별 | B3: 연령 | C3: =LEFT(E3,4)-1&"년" -> 2005년 | E3: =LEFT(G3,4)-1&"년" -> 2006년 | G3: =LEFT(I3,4)-1&"년" -> 2007년 | I3: =LEFT(K3,4)-1&"년" -> 2008년 | K3: =LEFT(M3,4)-1&"년" -> 2009년 | M3: =LEFT(O3,4)-1&"년" -> 2010년 | O3: =LEFT(Q3,4)-1&"년" -> 2011년 | Q3: =LEFT(S3,4)-1&"년" -> 2012년 | S3: =LEFT(U3,4)-1&"년" -> 2013년 | U3: =LEFT(W3,4)-1&"년" -> 2014년 | W3: =LEFT(Y3,4)-1&"년" -> 2015년 | Y3: =LEFT(AA3,4)-1&"년" -> 2016년 | AA3: =LEFT(AC3,4)-1&"년" -> 2017년 | AC3: =LEFT(AE3,4)-1&"년" -> 2018년 | AE3: =LEFT(AG3,4)-1&"년" -> 2019년 | AG3: =LEFT(AI3,4)-1&"년" -> 2020년 | AI3: =LEFT(AK3,4)-1&"년" -> 2021년 | AK3: =LEFT(AM3,4)-1&"년" -> 2022년 | AM3: =LEFT(AO3,4)-1&"년" -> 2023년 | AO3: =LEFT(AQ3,4)-1&"년" -> 2024년 | AQ3: =표지!G5&"년" -> 2025년 | AS3: 연령 | AT3: 성별
C4: 이동자수 | D4: 이동률 | E4: 이동자수 | F4: 이동률 | G4: 이동자수 | H4: 이동률 | I4: 이동자수 | J4: 이동률 | K4: 이동자수 | L4: 이동률 | M4: 이동자수 | N4: 이동률 | O4: 이동자수 | P4: 이동률 | Q4: 이동자수 | R4: 이동률 | S4: 이동자수 | T4: 이동률 | U4: 이동자수 | V4: 이동률 | W4: 이동자수 | X4: 이동률 | Y4: 이동자수 | Z4: 이동률 | AA4: 이동자수 | AB4: 이동률 | AC4: 이동자수 | AD4: 이동률 | AE4: 이동자수 | AF4: 이동률 | AG4: 이동자수 | AH4: 이동률 | AI4: 이동자수 | AJ4: 이동률 | AK4: 이동자수 | AL4: 이동률 | AM4: 이동자수 | AN4: 이동률 | AO4: 이동자수 | AP4: 이동률 | AQ4: 이동자수 | AR4: 이동률
A5: 남녀전체 | AT5: 남녀전체
B6: 계 | C6: 8795397 | D6: 18.066655 | E6: 9342074 | F6: 19.109515 | G6: 9070102 | H6: 18.4613 | I6: 8808256 | J6: 17.8288 | K6: 8487275 | L6: 17.091884 | M6: 8226594 | N6: 16.492833 | O6: 8127195 | P6: 16.218231 | Q6: 7506691 | R6: 14.910403 | S6: 7411784 | T6: 14.659687 | U6: 7629098 | V6: 15.028809 | W6: 7755286 | X6: 15.220853 | Y6: 7378430 | Z6: 14.435533 | AA6: 7154226 | AB6: 13.964723 | AC6: 7297099 | AD6: 14.224121 | AE6: 7104398 | AF6: 13.838634 | AG6: 7735491 | AH6: 15.064465 | AI6: 7213422 | AJ6: 14.052143 | AK6: 6152155 | AL6: 12.002062 | AM6: 6128738 | AN6: 11.982856 | AO6: 6283319 | AP6: 12.311241 | AQ6: 6117784 | AR6: 12.010032 | AS6: 계
B7: 0- 4세 | C7: 603115 | D7: 23.827566 | E7: 598523 | F7: 25.221454 | G7: 554494 | H7: 23.94028 | I7: 543050 | J7: 23.581014 | K7: 527469 | L7: 23.167711 | M7: 500343 | N7: 21.933325 | O7: 505325 | P7: 21.842815 | Q7: 457889 | R7: 19.699683 | S7: 459745 | T7: 19.896085 | U7: 461415 | V7: 20.08559 | W7: 451344 | X7: 19.796007 | Y7: 417530 | Z7: 18.682084 | AA7: 387118 | AB7: 18.080062 | AC7: 379926 | AD7: 18.750953 | AE7: 337461 | AF7: 17.675676 | AG7: 337233 | AH7: 19.154023 | AI7: 273394 | AJ7: 17.050807 | AK7: 217118 | AL7: 14.682744 | AM7: 231728 | AN7: 16.782095 | AO7: 230839 | AP7: 17.717309 | AQ7: 202025 | AR7: 15.997469 | AS7: 0- 4세
B8: 5- 9세 | C8: 613104 | D8: 18.590807 | E8: 619971 | F8: 19.38558 | G8: 560413 | H8: 18.407155 | I8: 522592 | J8: 18.139717 | K8: 474368 | L8: 17.355932 | M8: 433848 | N8: 16.964981 | O8: 402505 | P8: 16.769791 | Q8: 359933 | R8: 15.346527 | S8: 359560 | T8: 15.410635 | U8: 357208 | V8: 15.475414 | W8: 348704 | X8: 15.067292 | Y8: 325398 | Z8: 13.867755 | AA8: 314134 | AB8: 13.32844 | AC8: 318132 | AD8: 13.593479 | AE8: 296505 | AF8: 12.762899 | AG8: 322547 | AH8: 13.991001 | AI8: 283262 | AJ8: 12.535642 | AK8: 227879 | AL8: 10.521424 | AM8: 227062 | AN8: 11.074926 | AO8: 221747 | AP8: 11.477517 | AQ8: 192129 | AR8: 10.761492 | AS8: 5- 9세
B9: 10-14세 | C9: 523625 | D9: 14.822526 | E9: 557515 | F9: 15.672764 | G9: 543745 | H9: 15.44262 | I9: 528646 | J9: 15.287654 | K9: 490984 | L9: 14.55168 | M9: 458085 | N9: 13.92073 | O9: 437008 | P9: 13.691374 | Q9: 376610 | R9: 12.390867 | S9: 343609 | T9: 11.941723 | U9: 327573 | V9: 11.992672 | W9: 307697 | X9: 12.033191 | Y9: 263887 | Z9: 10.992269 | AA9: 245501 | AB9: 10.463682 | AC9: 247954 | AD9: 10.622714 | AE9: 237099 | AF9: 10.268787 | AG9: 249077 | AH9: 10.75934 | AI9: 226828 | AJ9: 9.6636955 | AK9: 191329 | AL9: 8.1147359 | AM9: 196255 | AN9: 8.381525 | AO9: 206209 | AP9: 8.8700093 | AQ9: 195144 | AR9: 8.4571683 | AS9: 10-14세
B10: 15-19세 | C10: 440970 | D10: 14.055255 | E10: 468347 | F10: 14.779995 | G10: 476548 | H10: 14.61135 | I10: 481190 | J10: 14.323245 | K10: 480721 | L10: 13.957346 | M10: 476305 | N10: 13.53393 | O10: 488089 | P10: 13.769633 | Q10: 443122 | R10: 12.628646 | S10: 429314 | T10: 12.456991 | U10: 426241 | V10: 12.669233 | W10: 423725 | X10: 12.906577 | Y10: 385388 | Z10: 12.09799 | AA10: 360288 | AB10: 11.874594 | AC10: 343080 | AD10: 11.945574 | AE10: 330065 | AF10: 12.111166 | AG10: 324253 | AH10: 12.710755 | AI10: 286349 | AJ10: 11.955787 | AK10: 254246 | AL10: 10.860883 | AM10: 252451 | AN10: 10.838147 | AO10: 260603 | AP10: 11.309471 | AQ10: 260317 | AR10: 11.267803 | AS10: 15-19세
B11: 20-24세 | C11: 795088 | D11: 20.907132 | E11: 791453 | F11: 21.974844 | G11: 725856 | H11: 21.408031 | I11: 651742 | J11: 20.204838 | K11: 593024 | L11: 18.831653 | M11: 577490 | N11: 18.463113 | O11: 577497 | P11: 18.273076 | Q11: 559264 | R11: 17.194003 | S11: 562797 | T11: 16.80453 | U11: 605311 | V11: 17.628093 | W11: 648271 | X11: 18.472206 | Y11: 639063 | Z11: 18.079777 | AA11: 625278 | AB11: 17.870401 | AC11: 636353 | AD11: 18.517954 | AE11: 645758 | AF11: 19.254512 | AG11: 714597 | AH11: 21.837993 | AI11: 689609 | AJ11: 21.719866 | AK11: 617539 | AL11: 20.423884 | AM11: 578264 | AN11: 20.207349 | AO11: 589196 | AP11: 21.700087 | AQ11: 568413 | AR11: 22.369191 | AS11: 20-24세
B12: 25-29세 | C12: 1191456 | D12: 30.593267 | E12: 1268234 | F12: 32.063956 | G12: 1252311 | H12: 31.19764 | I12: 1197850 | J12: 29.589994 | K12: 1108256 | L12: 27.860538 | M12: 1040901 | N12: 27.394258 | O12: 966132 | P12: 26.84248 | Q12: 860960 | R12: 25.394031 | S12: 794762 | T12: 24.630181 | U12: 796270 | V12: 25.267175 | W12: 814025 | X12: 26.005203 | Y12: 802204 | Z12: 25.376012 | AA12: 818455 | AB12: 25.16563 | AC12: 882610 | AD12: 26.362581 | AE12: 918309 | AF12: 26.766013 | AG12: 1014066 | AH12: 28.930497 | AI12: 1005438 | AJ12: 28.482865 | AK12: 887067 | AL12: 25.39477 | AM12: 854386 | AN12: 24.917029 | AO12: 860133 | AP12: 25.711662 | AQ12: 844710 | AR12: 25.887511 | AS12: 25-29세
B13: 30-34세 | C13: 1179752 | D13: 26.565307 | E13: 1211685 | F13: 28.290508 | G13: 1127873 | H13: 27.288414 | I13: 1065413 | J13: 26.702703 | K13: 1012287 | L13: 26.031508 | M13: 1016329 | N13: 26.105651 | O13: 1029945 | P13: 26.059179 | Q13: 990866 | R13: 24.708889 | S13: 993697 | T13: 24.584083 | U13: 1007542 | V13: 25.366266 | W13: 967038 | X13: 25.471756 | Y13: 885522 | Z13: 24.614585 | AA13: 821308 | AB13: 24.23062 | AC13: 803519 | AD13: 24.898773 | AE13: 775276 | AF13: 24.602822 | AG13: 846573 | AH13: 27.042058 | AI13: 808172 | AJ13: 25.554814 | AK13: 722268 | AL13: 22.209943 | AM13: 777528 | AN13: 23.242511 | AO13: 826003 | AP13: 24.108936 | AQ13: 817812 | AR13: 23.377131 | AS13: 30-34세
B14: 35-39세 | C14: 879731 | D14: 19.911092 | E14: 968801 | F14: 21.497262 | G14: 947774 | H14: 20.687924 | I14: 930318 | J14: 20.308439 | K14: 899414 | L14: 19.84491 | M14: 865771 | N14: 19.536122 | O14: 822214 | P14: 19.238202 | Q14: 738788 | R14: 17.918883 | S14: 720702 | T14: 18.122666 | U14: 732542 | V14: 18.903612 | W14: 748472 | X14: 19.283577 | Y14: 729964 | Z14: 18.521561 | AA14: 729543 | AB14: 18.242684 | AC14: 757182 | AD14: 18.78211 | AE14: 720238 | AF14: 18.186354 | AG14: 760067 | AH14: 20.073404 | AI14: 661979 | AJ14: 18.436004 | AK14: 532993 | AL14: 15.75098 | AM14: 541608 | AN14: 16.812992 | AO14: 551073 | AP14: 17.519787 | AQ14: 530308 | AR14: 16.973712 | AS14: 35-39세
B15: 40-44세 | C15: 708066 | D15: 16.320665 | E15: 739656 | F15: 17.453757 | G15: 716960 | H15: 17.198069 | I15: 708452 | J15: 16.777971 | K15: 716999 | L15: 16.552408 | M15: 705022 | N15: 16.010295 | O15: 705164 | P15: 15.694833 | Q15: 659651 | R15: 14.447496 | S15: 654721 | T15: 14.355984 | U15: 666813 | V15: 14.787198 | W15: 663890 | X15: 15.052843 | Y15: 598840 | Z15: 14.076416 | AA15: 562891 | AB15: 13.713345 | AC15: 556042 | AD15: 14.041908 | AE15: 528184 | AF15: 13.693708 | AG15: 588059 | AH15: 15.219883 | AI15: 545260 | AJ15: 13.892399 | AK15: 469084 | AL15: 11.779241 | AM15: 486928 | AN15: 12.132958 | AO15: 494893 | AP15: 12.553631 | AQ15: 460267 | AR15: 12.212269 | AS15: 40-44세
B16: 45-49세 | C16: 566334 | D16: 14.206004 | E16: 642658 | F16: 15.373972 | G16: 640801 | H16: 14.800555 | I16: 645574 | J16: 14.737612 | K16: 625022 | L16: 14.305896 | M16: 602308 | N16: 13.967906 | O16: 576422 | P16: 13.672002 | Q16: 527456 | R16: 12.717233 | S16: 521701 | T16: 12.433474 | U16: 559029 | V16: 12.996171 | W16: 580947 | X16: 13.285111 | Y16: 558818 | Z16: 12.523879 | AA16: 548278 | AB16: 12.087796 | AC16: 554187 | AD16: 12.229422 | AE16: 534216 | AF16: 11.927846 | AG16: 566053 | AH16: 12.921348 | AI16: 494802 | AJ16: 11.704013 | AK16: 401090 | AL16: 9.8343902 | AM16: 388233 | AN16: 9.8717218 | AO16: 390873 | AP16: 10.205311 | AQ16: 387184 | AR16: 10.09442 | AS16: 45-49세
B17: 50-54세 | C17: 356797 | D17: 12.609432 | E17: 418233 | F17: 13.560695 | G17: 432349 | H17: 13.105436 | I17: 459667 | J17: 13.112962 | K17: 479764 | L17: 12.83175 | M17: 495162 | N17: 12.550388 | O17: 519775 | P17: 12.553063 | Q17: 488747 | R17: 11.394539 | S17: 489732 | T17: 11.293346 | U17: 510132 | V17: 11.80265 | W17: 523217 | X17: 12.264122 | Y17: 481855 | Z17: 11.549293 | AA17: 459858 | AB17: 11.200548 | AC17: 467739 | AD17: 11.257023 | AE17: 467459 | AF17: 10.976166 | AG17: 519685 | AH17: 11.998377 | AI17: 489341 | AJ17: 11.063997 | AK17: 417460 | AL17: 9.2869167 | AM17: 408201 | AN17: 9.0948689 | AO17: 414615 | AP17: 9.3496859 | AQ17: 398718 | AR17: 9.1959776 | AS17: 50-54세
... B23: 80세이상 | C23: 79338 | D23: 12.056283 | E23: 92586 | F23: 13.376435 | G23: 105994 | H23: 14.455538 | I23: 95862 | J23: 12.212614 | K23: 102329 | L23: 12.11983 | M23: 100668 | N23: 11.095558 | O23: 105146 | P23: 10.853781 | Q23: 101651 | R23: 9.8006057 | S23: 107772 | T23: 9.6589972 | U23: 114863 | V23: 9.5185414 | W23: 121387 | X23: 9.2514938 | Y23: 124562 | Z23: 8.7615444 | AA23: 125241 | AB23: 8.1755924 | AC23: 135741 | AD23: 8.2563099 | AE23: 135224 | AF23: 7.6428009 | AG23: 149009 | AH23: 7.8603184 | AI23: 150572 | AJ23: 7.4435426 | AK23: 130144 | AL23: 5.9960212 | AM23: 129517 | AN23: 5.6373971 | AO23: 131722 | AP23: 5.5095273 | AQ23: 136120 | AR23: 5.5151155 | AS23: 80세이상
A24: 남자 | B24: 계 | C24: 4394364 | D24: 18.002562 | E24: 4656686 | F24: 19.001748 | G24: 4515566 | H24: 18.337974 | I24: 4408493 | J24: 17.807004 | K24: 4248697 | L24: 17.079215 | M24: 4136960 | N24: 16.562969 | O24: 4090513 | P24: 16.308698 | Q24: 3788912 | R24: 15.04283 | S24: 3747706 | T24: 14.82307 | U24: 3869608 | V24: 15.249996 | W24: 3939576 | X24: 15.47477 | Y24: 3755734 | Z24: 14.712321 | AA24: 3649815 | AB24: 14.270049 | AC24: 3715518 | AD24: 14.51263 | AE24: 3631378 | AF24: 14.179896 | AG24: 3932208 | AH24: 15.35654 | AI24: 3688955 | AJ24: 14.416117 | AK24: 3160337 | AL24: 12.374048 | AM24: 3149555 | AN24: 12.366142 | AO24: 3213510 | AP24: 12.651364 | AQ24: 3139371 | AR24: 12.389237 | AS24: 계 | AT24: 남자
B25: 0- 4세 | C25: 312001 | D25: 23.664442 | E25: 309450 | F25: 25.083063 | G25: 285933 | H25: 23.803768 | I25: 280541 | J25: 23.553794 | K25: 271603 | L25: 23.106241 | M25: 257926 | N25: 21.924466 | O25: 260716 | P25: 21.876314 | Q25: 235924 | R25: 19.72147 | S25: 237234 | T25: 19.960002 | U25: 237196 | V25: 20.093251 | W25: 232172 | X25: 19.839335 | Y25: 213324 | Z25: 18.613701 | AA25: 198429 | AB25: 18.075595 | AC25: 195243 | AD25: 18.791109 | AE25: 173325 | AF25: 17.700475 | AG25: 173346 | AH25: 19.192894 | AI25: 141014 | AJ25: 17.141006 | AK25: 111639 | AL25: 14.721555 | AM25: 119024 | AN25: 16.824298 | AO25: 118189 | AP25: 17.716568 | AQ25: 103676 | AR25: 16.034334 | AS25: 0- 4세
B26: 5- 9세 | C26: 317872 | D26: 18.397798 | E26: 321382 | F26: 19.232891 | G26: 289822 | H26: 18.228773 | I26: 270042 | J26: 17.949645 | K26: 245028 | L26: 17.192088 | M26: 224553 | N26: 16.867362 | O26: 208158 | P26: 16.689785 | Q26: 185580 | R26: 15.263697 | S26: 183971 | T26: 15.250256 | U26: 184004 | V26: 15.444481 | W26: 179019 | X26: 15.0043 | Y26: 167006 | Z26: 13.822643 | AA26: 161087 | AB26: 13.286775 | AC26: 162704 | AD26: 13.524562 | AE26: 152083 | AF26: 12.747797 | AG26: 164572 | AH26: 13.916694 | AI26: 144191 | AJ26: 12.451609 | AK26: 116262 | AL26: 10.476102 | AM26: 116209 | AN26: 11.058498 | AO26: 113551 | AP26: 11.462729 | AQ26: 98526 | AR26: 10.761912 | AS26: 5- 9세
B27: 10-14세 | C27: 276263 | D27: 14.701605 | E27: 294149 | F27: 15.56143 | G27: 286306 | H27: 15.334212 | I27: 276298 | J27: 15.130149 | K27: 256986 | L27: 14.486499 | M27: 238829 | N27: 13.857716 | O27: 228754 | P27: 13.720454 | Q27: 197789 | R27: 12.465046 | S27: 181030 | T27: 12.051634 | U27: 172334 | V27: 12.102421 | W27: 161522 | X27: 12.136901 | Y27: 139294 | Z27: 11.168752 | AA27: 129396 | AB27: 10.641608 | AC27: 129296 | AD27: 10.717009 | AE27: 123789 | AF27: 10.391164 | AG27: 130340 | AH27: 10.925609 | AI27: 118502 | AJ27: 9.8087695 | AK27: 100127 | AL27: 8.2585235 | AM27: 102385 | AN27: 8.5091017 | AO27: 107054 | AP27: 8.9701136 | AQ27: 101951 | AR27: 8.6168906 | AS27: 10-14세
B28: 15-19세 | C28: 225854 | D28: 13.713753 | E28: 239672 | F28: 14.361102 | G28: 245055 | H28: 14.228944 | I28: 248456 | J28: 13.959434 | K28: 248632 | L28: 13.588431 | M28: 248562 | N28: 13.285904 | O28: 254896 | P28: 13.54045 | Q28: 232638 | R28: 12.510406 | S28: 225278 | T28: 12.385064 | U28: 223360 | V28: 12.634892 | W28: 220956 | X28: 12.858577 | Y28: 199929 | Z28: 12.023512 | AA28: 186730 | AB28: 11.79835 | AC28: 176285 | AD28: 11.770303 | AE28: 169771 | AF28: 11.964652 | AG28: 166382 | AH28: 12.548552 | AI28: 147443 | AJ28: 11.866554 | AK28: 128868 | AL28: 10.638177 | AM28: 127595 | AN28: 10.614757 | AO28: 130703 | AP28: 11.01088 | AQ28: 130215 | AR28: 10.954699 | AS28: 15-19세
B29: 20-24세 | C29: 371243 | D29: 18.947069 | E29: 372444 | F29: 20.016908 | G29: 345773 | H29: 19.684645 | I29: 315026 | J29: 18.787243 | K29: 287596 | L29: 17.503245 | M29: 283883 | N29: 17.322572 | O29: 287048 | P29: 17.280285 | Q29: 277355 | R29: 16.182248 | S29: 280988 | T29: 15.868717 | U29: 303649 | V29: 16.677679 | W29: 326900 | X29: 17.552903 | Y29: 320227 | Z29: 17.086246 | AA29: 311749 | AB29: 16.839501 | AC29: 310196 | AD29: 17.132363 | AE29: 310352 | AF29: 17.641816 | AG29: 334628 | AH29: 19.572025 | AI29: 324815 | AJ29: 19.634506 | AK29: 292368 | AL29: 18.572965 | AM29: 275222 | AN29: 18.480056 | AO29: 281529 | AP29: 19.9569 | AQ29: 271863 | AR29: 20.629987 | AS29: 20-24세
B30: 25-29세 | C30: 602605 | D30: 30.296335 | E30: 640255 | F30: 31.651449 | G30: 631466 | H30: 30.71146 | I30: 609508 | J30: 29.382036 | K30: 561628 | L30: 27.542584 | M30: 529788 | N30: 27.141752 | O30: 493907 | P30: 26.661646 | Q30: 439500 | R30: 25.140921 | S30: 407840 | T30: 24.452305 | U30: 412100 | V30: 25.215272 | W30: 425015 | X30: 26.067759 | Y30: 421462 | Z30: 25.50369 | AA30: 433168 | AB30: 25.400489 | AC30: 466923 | AD30: 26.497873 | AE30: 488903 | AF30: 26.991606 | AG30: 531266 | AH30: 28.674751 | AI30: 536486 | AJ30: 28.767023 | AK30: 474561 | AL30: 25.76425 | AM30: 452356 | AN30: 25.120199 | AO30: 448310 | AP30: 25.631086 | AQ30: 439801 | AR30: 25.879081 | AS30: 25-29세
B31: 30-34세 | C31: 622185 | D31: 27.459341 | E31: 636513 | F31: 29.155315 | G31: 592250 | H31: 28.164319 | I31: 559194 | J31: 27.523927 | K31: 528981 | L31: 26.67262 | M31: 532176 | N31: 26.815737 | O31: 537078 | P31: 26.636744 | Q31: 515548 | R31: 25.175111 | S31: 518319 | T31: 25.112415 | U31: 526744 | V31: 25.965734 | W31: 507347 | X31: 26.113209 | Y31: 467289 | Z31: 25.336188 | AA31: 435671 | AB31: 25.028609 | AC31: 424516 | AD31: 25.553011 | AE31: 412910 | AF31: 25.369349 | AG31: 450570 | AH31: 27.746303 | AI31: 437008 | AJ31: 26.540876 | AK31: 389682 | AL31: 22.940958 | AM31: 415822 | AN31: 23.704205 | AO31: 437849 | AP31: 24.290182 | AQ31: 435709 | AR31: 23.64115 | AS31: 30-34세
B32: 35-39세 | C32: 462961 | D32: 20.591007 | E32: 508793 | F32: 22.226314 | G32: 497302 | H32: 21.359632 | I32: 489830 | J32: 20.979761 | K32: 476058 | L32: 20.59086 | M32: 458786 | N32: 20.298397 | O32: 435988 | P32: 20.027874 | Q32: 393074 | R32: 18.760073 | S32: 383498 | T32: 18.969855 | U32: 390807 | V32: 19.814654 | W32: 398569 | X32: 20.186852 | Y32: 390276 | Z32: 19.454144 | AA32: 388484 | AB32: 19.066016 | AC32: 403629 | AD32: 19.649145 | AE32: 384999 | AF32: 19.074824 | AG32: 405379 | AH32: 20.965682 | AI32: 356160 | AJ32: 19.389231 | AK32: 288137 | AL32: 16.619571 | AM32: 293535 | AN32: 17.746591 | AO32: 298377 | AP32: 18.416355 | AQ32: 287566 | AR32: 17.796787 | AS32: 35-39세
B33: 40-44세 | C33: 363757 | D33: 16.402585 | E33: 381844 | F33: 17.559493 | G33: 370458 | H33: 17.318567 | I33: 365323 | J33: 16.960851 | K33: 371155 | L33: 16.851808 | M33: 366280 | N33: 16.367861 | O33: 364703 | P33: 16.002856 | Q33: 343796 | R33: 14.838358 | S33: 342968 | T33: 14.782237 | U33: 350261 | V33: 15.258653 | W33: 348511 | X33: 15.525099 | Y33: 317045 | Z33: 14.659752 | AA33: 297834 | AB33: 14.304899 | AC33: 295225 | AD33: 14.691977 | AE33: 281179 | AF33: 14.347998 | AG33: 314243 | AH33: 16.013712 | AI33: 292798 | AJ33: 14.675385 | AK33: 251201 | AL33: 12.39747 | AM33: 260932 | AN33: 12.779521 | AO33: 263976 | AP33: 13.161225 | AQ33: 246559 | AR33: 12.835879 | AS33: 40-44세
B34: 45-49세 | C34: 286498 | D34: 14.170954 | E34: 324232 | F34: 15.302704 | G34: 327124 | H34: 14.905276 | I34: 330370 | J34: 14.855093 | K34: 322719 | L34: 14.522311 | M34: 309761 | N34: 14.103823 | O34: 297325 | P34: 13.790149 | Q34: 274519 | R34: 12.94299 | S34: 270050 | T34: 12.663196 | U34: 288338 | V34: 13.23262 | W34: 298480 | X34: 13.478425 | Y34: 289135 | Z34: 12.816836 | AA34: 285022 | AB34: 12.420477 | AC34: 288863 | AD34: 12.564139 | AE34: 280371 | AF34: 12.329246 | AG34: 296961 | AH34: 13.348422 | AI34: 260471 | AJ34: 12.142083 | AK34: 211649 | AL34: 10.24887 | AM34: 205376 | AN34: 10.310185 | AO34: 205985 | AP34: 10.605483 | AQ34: 204883 | AR34: 10.538821 | AS34: 45-49세
B35: 50-54세 | C35: 178043 | D35: 12.524612 | E35: 206272 | F35: 13.32993 | G35: 213945 | H35: 12.903395 | I35: 227192 | J35: 12.859536 | K35: 238790 | L35: 12.67019 | M35: 246128 | N35: 12.386522 | O35: 258228 | P35: 12.385119 | Q35: 245730 | R35: 11.373488 | S35: 247783 | T35: 11.32598 | U35: 259186 | V35: 11.863748 | W35: 266023 | X35: 12.316473 | Y35: 247395 | Z35: 11.662369 | AA35: 237166 | AB35: 11.358247 | AC35: 241177 | AD35: 11.47941 | AE35: 242359 | AF35: 11.288378 | AG35: 268871 | AH35: 12.309703 | AI35: 253065 | AJ35: 11.357236 | AK35: 217313 | AL35: 9.5879713 | AM35: 213066 | AN35: 9.389762 | AO35: 215340 | AP35: 9.5977665 | AQ35: 208493 | AR35: 9.5028325 | AS35: 50-54세
B36: 55-59세 | C36: 121419 | D36: 10.879839 | E36: 136050 | F36: 11.777161 | G36: 136514 | H36: 11.436877 | I36: 143104 | J36: 11.583504 | K36: 144182 | L36: 11.215467 | M36: 153783 | N36: 11.124695 | O36: 167545 | P36: 11.11667 | Q36: 164703 | R36: 10.191374 | S36: 173530 | T36: 10.080192 | U36: 197218 | V36: 10.74027 | W36: 216272 | X36: 11.163238 | Y36: 219055 | Z36: 10.768189 | AA36: 216195 | AB36: 10.245611 | AC36: 225386 | AD36: 10.537881 | AE36: 214434 | AF36: 10.03484 | AG36: 234698 | AH36: 11.094445 | AI36: 215317 | AJ36: 10.345164 | AK36: 179770 | AL36: 8.7715275 | AM36: 173945 | AN36: 8.4400029 | AO36: 183940 | AP36: 8.7356444 | AQ36: 186544 | AR36: 8.7108914 | AS36: 55-59세
... B41: 80세이상 | C41: 20604 | D41: 10.708745 | E41: 23740 | F41: 11.763103 | G41: 26067 | H41: 12.234036 | I41: 23658 | J41: 10.426964 | K41: 24602 | L41: 10.095448 | M41: 23801 | N41: 9.1056556 | O41: 24594 | P41: 8.8243525 | Q41: 23384 | R41: 7.781736 | S41: 24823 | T41: 7.582216 | U41: 26990 | V41: 7.5015252 | W41: 29740 | X41: 7.4639508 | Y41: 31162 | Z41: 7.0851229 | AA41: 31305 | AB41: 6.4857306 | AC41: 34534 | AD41: 6.5499707 | AE41: 34921 | AF41: 6.0498335 | AG41: 39431 | AH41: 6.281017 | AI41: 40649 | AJ41: 5.984095 | AK41: 35498 | AL41: 4.7890184 | AM41: 36267 | AN41: 4.5617347 | AO41: 37430 | AP41: 4.4847509 | AQ41: 38904 | AR41: 4.4700363 | AS41: 80세이상
A42: 여자 | B42: 계 | C42: 4401033 | D42: 18.131108 | E42: 4685388 | F42: 19.217841 | G42: 4554536 | H42: 18.585219 | I42: 4399763 | J42: 17.850693 | K42: 4238578 | L42: 17.104601 | M42: 4089634 | N42: 16.422486 | O42: 4036682 | P42: 16.127576 | Q42: 3717779 | R42: 14.77782 | S42: 3664078 | T42: 14.496259 | U42: 3759490 | V42: 14.807746 | W42: 3815710 | X42: 14.967289 | Y42: 3622696 | Z42: 14.159366 | AA42: 3504411 | AB42: 13.660316 | AC42: 3581581 | AD42: 13.936699 | AE42: 3473020 | AF42: 13.498946 | AG42: 3803283 | AH42: 14.773945 | AI42: 3524467 | AJ42: 13.69036 | AK42: 2991818 | AL42: 11.632666 | AM42: 2979183 | AN42: 11.602669 | AO42: 3069809 | AP42: 11.974252 | AQ42: 2978413 | AR42: 11.634677 | AS42: 계 | AT42: 여자
B43: 0- 4세 | C43: 291114 | D43: 24.004908 | E43: 289073 | F43: 25.371302 | G43: 268561 | H43: 24.087355 | I43: 262509 | J43: 23.610152 | K43: 255866 | L43: 23.23332 | M43: 242417 | N43: 21.942757 | O43: 244609 | P43: 21.807223 | Q43: 221965 | R43: 19.676562 | S43: 222511 | T43: 19.828388 | U43: 224219 | V43: 20.077491 | W43: 219172 | X43: 19.750314 | Y43: 204206 | Z43: 18.754058 | AA43: 188689 | AB43: 18.084763 | AC43: 184683 | AD43: 18.708697 | AE43: 164136 | AF43: 17.649573 | AG43: 163887 | AH43: 19.113089 | AI43: 132380 | AJ43: 16.955774 | AK43: 105479 | AL43: 14.641889 | AM43: 112704 | AN43: 16.737766 | AO43: 112650 | AP43: 17.718087 | AQ43: 98349 | AR43: 15.958804 | AS43: 0- 4세
B44: 5- 9세 | C44: 295232 | D44: 18.803185 | E44: 298589 | F44: 19.552643 | G44: 270591 | H44: 18.602127 | I44: 252550 | J44: 18.347457 | K44: 229340 | L44: 17.53447 | M44: 209295 | N44: 17.07098 | O44: 194347 | P44: 16.856338 | Q44: 174353 | R44: 15.435684 | S44: 175589 | T44: 15.582328 | U44: 173204 | V44: 15.508399 | W44: 169685 | X44: 15.134326 | Y44: 158392 | Z44: 13.915641 | AA44: 153047 | AB44: 13.372577 | AC44: 155428 | AD44: 13.666379 | AE44: 144422 | AF44: 12.778842 | AG44: 157975 | AH44: 14.06926 | AI44: 139071 | AJ44: 12.623974 | AK44: 111617 | AL44: 10.569051 | AM44: 110853 | AN44: 11.092194 | AO44: 108196 | AP44: 11.493077 | AQ44: 93603 | AR44: 10.761056 | AS44: 5- 9세
B45: 10-14세 | C45: 247362 | D45: 14.959948 | E45: 263366 | F45: 15.799009 | G45: 257439 | H45: 15.564998 | I45: 252348 | J45: 15.463912 | K45: 233998 | L45: 14.623934 | M45: 219256 | N45: 13.990024 | O45: 208254 | P45: 13.659574 | Q45: 178821 | R45: 12.309841 | S45: 162579 | T45: 11.821675 | U45: 155239 | V45: 11.873136 | W45: 146175 | X45: 11.920625 | Y45: 124593 | Z45: 10.80145 | AA45: 116105 | AB45: 10.27227 | AC45: 118658 | AD45: 10.521835 | AE45: 113310 | AF45: 10.138345 | AG45: 118737 | AH45: 10.582545 | AI45: 108326 | AJ45: 9.5098218 | AK45: 91202 | AL45: 7.962535 | AM45: 93870 | AN45: 8.2466673 | AO45: 99155 | AP45: 8.7644088 | AQ45: 93193 | AR45: 8.289083 | AS45: 10-14세
B46: 15-19세 | C46: 215116 | D46: 14.432598 | E46: 228675 | F46: 15.246088 | G46: 231493 | H46: 15.03921 | I46: 232734 | J46: 14.733152 | K46: 232089 | L46: 14.375438 | M46: 227743 | N46: 13.815417 | O46: 233193 | P46: 14.029187 | Q46: 210484 | R46: 12.761958 | S46: 204036 | T46: 12.537383 | U46: 202881 | V46: 12.707256 | W46: 202769 | X46: 12.959293 | Y46: 185459 | Z46: 12.179319 | AA46: 173558 | AB46: 11.957733 | AC46: 166795 | AD46: 12.136583 | AE46: 160294 | AF46: 12.270306 | AG46: 157871 | AH46: 12.886303 | AI46: 138906 | AJ46: 12.051985 | AK46: 125378 | AL46: 11.09972 | AM46: 124856 | AN46: 11.076365 | AO46: 129900 | AP46: 11.62671 | AQ46: 130102 | AR46: 11.599617 | AS46: 15-19세
B47: 20-24세 | C47: 423845 | D47: 22.990298 | E47: 419009 | F47: 24.067353 | G47: 380083 | H47: 23.260666 | I47: 336716 | J47: 21.739532 | K47: 305428 | L47: 20.281013 | M47: 293607 | N47: 19.718402 | O47: 290449 | P47: 19.373069 | Q47: 281909 | R47: 18.320971 | S47: 281809 | T47: 17.854364 | U47: 301662 | V47: 18.70082 | W47: 321371 | X47: 19.511666 | Y47: 318836 | Z47: 19.201158 | AA47: 313529 | AB47: 19.028709 | AC47: 326157 | AD47: 20.061003 | AE47: 335406 | AF47: 21.03364 | AG47: 379969 | AH47: 24.317409 | AI47: 364794 | AJ47: 23.988416 | AK47: 325171 | AL47: 22.434049 | AM47: 303042 | AN47: 22.081815 | AO47: 307667 | AP47: 23.585178 | AQ47: 296550 | AR47: 24.242835 | AS47: 20-24세
B48: 25-29세 | C48: 588851 | D48: 30.903222 | E48: 627979 | F48: 32.49573 | G48: 620845 | H48: 31.708185 | I48: 588342 | J48: 29.808561 | K48: 546628 | L48: 28.194955 | M48: 511113 | N48: 27.660998 | O48: 472225 | P48: 27.03426 | Q48: 421460 | R48: 25.663462 | S48: 386922 | T48: 24.820496 | U48: 384170 | V48: 25.323089 | W48: 389010 | X48: 25.937182 | Y48: 380742 | Z48: 25.236161 | AA48: 385287 | AB48: 24.906718 | AC48: 415687 | AD48: 26.212252 | AE48: 429406 | AF48: 26.513695 | AG48: 482800 | AH48: 29.217241 | AI48: 468952 | AJ48: 28.164575 | AK48: 412506 | AL48: 24.982603 | AM48: 402030 | AN48: 24.692321 | AO48: 411823 | AP48: 25.799954 | AQ48: 404909 | AR48: 25.896674 | AS48: 25-29세
B49: 30-34세 | C49: 557567 | D49: 25.63398 | E49: 575172 | F49: 27.391373 | G49: 535623 | H49: 26.381224 | I49: 506219 | J49: 25.850686 | K49: 483306 | L49: 25.364229 | M49: 484153 | N49: 25.36729 | O49: 492867 | P49: 25.457664 | Q49: 475318 | R49: 24.222334 | S49: 475378 | T49: 24.032792 | U49: 480798 | V49: 24.740502 | W49: 459691 | X49: 24.799421 | Y49: 418233 | Z49: 23.855462 | AA49: 385637 | AB49: 23.388184 | AC49: 379003 | AD49: 24.204638 | AE49: 362366 | AF49: 23.78396 | AG49: 396003 | AH49: 26.283013 | AI49: 371164 | AJ49: 24.483808 | AK49: 332586 | AL49: 21.410569 | AM49: 361706 | AN49: 22.733478 | AO49: 388154 | AP49: 23.907704 | AQ49: 382103 | AR49: 23.083164 | AS49: 30-34세
...

Sheet 3. 시도별이동자추이
A1: ="3. 시도별 이동자 수 추이, "&B5&"-"&B25 -> 3. 시도별 이동자 수 추이, 2005-2025
V2: (단위 : 명)
A3: 시 도 연 도 | C3: 전국 | D3: 서울 | E3: 부산 | F3: 대구 | G3: 인천 | H3: 광주 | I3: 대전 | J3: 울산 | K3: 세종 | L3: 경기 | M3: 강원 | N3: 충북 | O3: 충남 | P3: 전북 | Q3: 전남 | R3: 경북 | S3: 경남 | T3: 제주 | U3: 시 도 연 도
A5: 전입 | B5: 2005 | C5: 8795397 | D5: 1990749 | E5: 552771 | F5: 440350 | G5: 502168 | H5: 290429 | I5: 287835 | J5: 169681 | K5: - | L5: 2197321 | M5: 245689 | N5: 235907 | O5: 325444 | P5: 311537 | Q5: 284412 | R5: 374711 | S5: 493352 | T5: 93041 | U5: 2005 | V5: 전입
B6: 2006 | C6: 9342074 | D6: 2173907 | E6: 559915 | F6: 428417 | G6: 523457 | H6: 301479 | I6: 294814 | J6: 174389 | K6: - | L6: 2459641 | M6: 254508 | N6: 245977 | O6: 336866 | P6: 327237 | Q6: 284276 | R6: 391486 | S6: 496713 | T6: 88992 | U6: 2006
B7: 2007 | C7: 9070102 | D7: 2078045 | E7: 529343 | F7: 399853 | G7: 576619 | H7: 286105 | I7: 283080 | J7: 180375 | K7: - | L7: 2306957 | M7: 245182 | N7: 253433 | O7: 355213 | P7: 332957 | Q7: 287179 | R7: 380925 | S7: 491542 | T7: 83294 | U7: 2007
B8: 2008 | C8: 8808256 | D8: 2025358 | E8: 514502 | F8: 409938 | G8: 565585 | H8: 268757 | I8: 263532 | J8: 181662 | K8: - | L8: 2195585 | M8: 252193 | N8: 244672 | O8: 355294 | P8: 322495 | Q8: 277906 | R8: 363297 | S8: 487356 | T8: 80124 | U8: 2008
B9: 2009 | C9: 8487275 | D9: 1873188 | E9: 519310 | F9: 398626 | G9: 478169 | H9: 293879 | I9: 252424 | J9: 159953 | K9: - | L9: 2175681 | M9: 249191 | N9: 232872 | O9: 329626 | P9: 314137 | Q9: 281051 | R9: 367244 | S9: 485349 | T9: 76575 | U9: 2009
B10: 2010 | C10: 8226594 | D10: 1733015 | E10: 519334 | F10: 370817 | G10: 462051 | H10: 268574 | I10: 262432 | J10: 161146 | K10: - | L10: 2168820 | M10: 241738 | N10: 235671 | O10: 317853 | P10: 305789 | Q10: 265600 | R10: 354575 | S10: 481955 | T10: 77224 | U10: 2010
B11: 2011 | C11: 8127195 | D11: 1721748 | E11: 508043 | F11: 370563 | G11: 499567 | H11: 260561 | I11: 264244 | J11: 164963 | K11: - | L11: 2062422 | M11: 236077 | N11: 228594 | O11: 321187 | P11: 308011 | Q11: 261239 | R11: 363511 | S11: 473757 | T11: 82708 | U11: 2011
B12: 2012 | C12: 7506691 | D12: 1555281 | E12: 461042 | F12: 348642 | G12: 468666 | H12: 228612 | I12: 239635 | J12: 161433 | K12: 32784 | L12: 1944962 | M12: 225896 | N12: 212263 | O12: 287195 | P12: 271835 | Q12: 239026 | R12: 335362 | S12: 414556 | T12: 79501 | U12: 2012
B13: 2013 | C13: 7411784 | D13: 1520090 | E13: 478451 | F13: 351873 | G13: 461613 | H13: 226696 | I13: 230858 | J13: 159492 | K13: 23805 | L13: 1895434 | M13: 217917 | N13: 215973 | O13: 281428 | P13: 258198 | Q13: 244329 | R13: 329118 | S13: 427658 | T13: 88851 | U13: 2013
B14: 2014 | C14: 7629098 | D14: 1573594 | E14: 485710 | F14: 350213 | G14: 452297 | H14: 243066 | I14: 239559 | J14: 176015 | K14: 56526 | L14: 1891775 | M14: 228369 | N14: 215944 | O14: 289627 | P14: 274337 | Q14: 260278 | R14: 337041 | S14: 462239 | T14: 92508 | U14: 2014
B15: 2015 | C15: 7755286 | D15: 1589431 | E15: 507031 | F15: 351424 | G15: 473223 | H15: 224603 | I15: 220774 | J15: 170393 | K15: 83994 | L15: 1993080 | M15: 227125 | N15: 214626 | O15: 289952 | P15: 261832 | Q15: 250104 | R15: 344730 | S15: 455384 | T15: 97580 | U15: 2015
B16: 2016 | C16: 7378430 | D16: 1515602 | E16: 459015 | F16: 328228 | G16: 441646 | H16: 213176 | I16: 219252 | J16: 148190 | K16: 65052 | L16: 1958593 | M16: 223484 | N16: 202679 | O16: 286764 | P16: 248188 | Q16: 234132 | R16: 315652 | S16: 411952 | T16: 106825 | U16: 2016
B17: 2017 | C17: 7154226 | D17: 1472937 | E17: 439073 | F17: 321182 | G17: 409465 | H17: 208138 | I17: 211449 | J17: 135199 | K17: 82073 | L17: 1888324 | M17: 211653 | N17: 197177 | O17: 288738 | P17: 232047 | Q17: 227504 | R17: 311061 | S17: 413179 | T17: 105027 | U17: 2017
B18: 2018 | C18: 7297099 | D18: 1439707 | E18: 416095 | F18: 321158 | G18: 433639 | H18: 218892 | I18: 212879 | J18: 127922 | K18: 86433 | L18: 2041715 | M18: 216398 | N18: 218886 | O18: 292305 | P18: 243324 | Q18: 224384 | R18: 309446 | S18: 389714 | T18: 104202 | U18: 2018
B19: 2019 | C19: 7104398 | D19: 1426493 | E19: 411704 | F19: 312419 | G19: 420014 | H19: 217130 | I19: 212424 | J19: 142056 | K19: 82398 | L19: 1940962 | M19: 217626 | N19: 211396 | O19: 258790 | P19: 228775 | Q19: 224483 | R19: 306511 | S19: 396251 | T19: 94966 | U19: 2019
B20: 2020 | C20: 7735491 | D20: 1578127 | E20: 491829 | F20: 347248 | G20: 444556 | H20: 226163 | I20: 232321 | J20: 136112 | K20: 78934 | L20: 2152572 | M20: 223354 | N20: 229895 | O20: 287127 | P20: 249083 | Q20: 239016 | R20: 317701 | S20: 403339 | T20: 98114 | U20: 2020
B21: 2021 | C21: 7213422 | D21: 1418187 | E21: 441323 | F21: 304761 | G21: 433137 | H21: 212888 | I21: 211565 | J21: 129880 | K21: 76912 | L21: 2036215 | M21: 217103 | N21: 214300 | O21: 282195 | P21: 223710 | Q21: 223619 | R21: 317866 | S21: 374782 | T21: 94979 | U21: 2021
B22: 2022 | C22: 6152155 | D22: 1201527 | E22: 383848 | F22: 265354 | G22: 395140 | H22: 182924 | I22: 198705 | J22: 107747 | K22: 65529 | L22: 1645990 | M22: 194864 | N22: 185419 | O22: 260488 | P22: 199432 | Q22: 191956 | R22: 263156 | S22: 323211 | T22: 86865 | U22: 2022
B23: 2023 | C23: 6128738 | D23: 1206963 | E23: 364271 | F23: 296291 | G23: 424127 | H23: 162916 | I23: 186084 | J23: 116641 | K23: 56050 | L23: 1681183 | M23: 173366 | N23: 186341 | O23: 266056 | P23: 188788 | Q23: 183557 | R23: 254287 | S23: 300309 | T23: 81508 | U23: 2023
... B25: 2025 | C25: 6117784 | D25: 1244928 | E25: 362416 | F25: 268468 | G25: 395525 | H25: 162873 | I25: 207372 | J25: 114205 | K25: 54355 | L25: 1628873 | M25: 182825 | N25: 199201 | O25: 251857 | P25: 195095 | Q25: 185748 | R25: 259920 | S25: 326535 | T25: 77588 | U25: 2025
A27: 전출 | V27: 전출
B28: 2005 | C28: 8795397 | D28: 2041756 | E28: 589746 | F28: 465300 | G28: 491203 | H28: 297762 | I28: 284625 | J28: 170073 | K28: - | L28: 2028470 | M28: 257162 | N28: 240615 | O28: 320445 | P28: 336014 | Q28: 304419 | R28: 386228 | S28: 487733 | T28: 93846 | U28: 2005
B29: 2006 | C29: 9342074 | D29: 2210458 | E29: 594601 | F29: 454076 | G29: 513839 | H29: 304209 | I29: 292499 | J29: 176800 | K29: - | L29: 2321008 | M29: 264068 | N29: 244227 | O29: 329811 | P29: 346399 | Q29: 308961 | R29: 394805 | S29: 495419 | T29: 90894 | U29: 2006
B30: 2007 | C30: 9070102 | D30: 2130928 | E30: 565419 | F30: 416398 | G30: 553898 | H30: 290248 | I30: 284128 | J30: 181367 | K30: - | L30: 2193857 | M30: 251328 | N30: 247741 | O30: 341850 | P30: 343831 | Q30: 303752 | R30: 395536 | S30: 483599 | T30: 86222 | U30: 2007
B31: 2008 | C31: 8808256 | D31: 2083352 | E31: 549106 | F31: 422676 | G31: 556166 | H31: 268310 | I31: 269142 | J31: 177756 | K31: - | L31: 2094988 | M31: 250883 | N31: 237759 | O31: 339765 | P31: 333045 | Q31: 291224 | R31: 377397 | S31: 474327 | T31: 82360 | U31: 2008
B32: 2009 | C32: 8487275 | D32: 1925452 | E32: 549094 | F32: 411288 | G32: 476071 | H32: 290771 | I32: 258182 | J32: 164984 | K32: - | L32: 2081528 | M32: 247373 | N32: 230351 | O32: 317511 | P32: 318943 | Q32: 288476 | R32: 375551 | S32: 474110 | T32: 77590 | U32: 2009
B33: 2010 | C33: 8226594 | D33: 1848038 | E33: 547800 | F33: 382657 | G33: 458439 | H33: 265043 | I33: 263477 | J33: 164671 | K33: - | L33: 2026383 | M33: 241183 | N33: 229707 | O33: 301675 | P33: 308237 | Q33: 275661 | R33: 358127 | S33: 478709 | T33: 76787 | U33: 2010
B34: 2011 | C34: 8127195 | D34: 1834806 | E34: 532906 | F34: 383310 | G34: 470758 | H34: 259282 | I34: 260900 | J34: 163091 | K34: - | L34: 1986623 | M34: 231424 | N34: 220515 | O34: 302546 | P34: 306290 | Q34: 266461 | R34: 358695 | S34: 469223 | T34: 80365 | U34: 2011
B35: 2012 | C35: 7506691 | D35: 1658928 | E35: 481652 | F35: 359206 | G35: 440872 | H35: 230437 | I35: 239136 | J35: 157427 | K35: 15291 | L35: 1862209 | M35: 225184 | N35: 207622 | O35: 277346 | P35: 275126 | Q35: 244080 | R35: 340222 | S35: 417328 | T35: 74625 | U35: 2012
B36: 2013 | C36: 7411784 | D36: 1620640 | E36: 496161 | F36: 363224 | G36: 439578 | H36: 229288 | I36: 230547 | J36: 157185 | K36: 15109 | L36: 1821303 | M36: 214931 | N36: 212860 | O36: 268053 | P36: 260395 | Q36: 246635 | R36: 330983 | S36: 423864 | T36: 81028 | U36: 2013
B37: 2014 | C37: 7629098 | D37: 1661425 | E37: 500802 | F37: 365739 | G37: 442973 | H37: 246043 | I37: 248397 | J37: 173229 | K37: 23070 | L37: 1834379 | M37: 226284 | N37: 213577 | O37: 279817 | P37: 276900 | Q37: 260874 | R37: 338029 | S37: 456164 | T37: 81396 | U37: 2014
B38: 2015 | C38: 7755286 | D38: 1726687 | E38: 520591 | F38: 364364 | G38: 463685 | H38: 233875 | I38: 241390 | J38: 170473 | K38: 30950 | L38: 1898312 | M38: 222352 | N38: 213188 | O38: 279680 | P38: 264662 | Q38: 246168 | R38: 345307 | S38: 450279 | T38: 83323 | U38: 2015
B39: 2016 | C39: 7378430 | D39: 1655859 | E39: 480407 | F39: 337488 | G39: 435869 | H39: 221074 | I39: 229883 | J39: 155812 | K39: 35236 | L39: 1824976 | M39: 221592 | N39: 197668 | O39: 271446 | P39: 252607 | Q39: 237337 | R39: 318803 | S39: 410180 | T39: 92193 | U39: 2016
B40: 2017 | C40: 7154226 | D40: 1571423 | E40: 467471 | F40: 333118 | G40: 411135 | H40: 216256 | I40: 227624 | J40: 147116 | K40: 47383 | L40: 1772162 | M40: 209618 | N40: 194915 | O40: 269337 | P40: 239253 | Q40: 230551 | R40: 316642 | S40: 409200 | T40: 91022 | U40: 2017
B41: 2018 | C41: 7297099 | D41: 1549937 | E41: 442854 | F41: 335400 | G41: 433706 | H41: 225108 | I41: 227632 | J41: 140576 | K41: 55000 | L41: 1871621 | M41: 220252 | N41: 213737 | O41: 282221 | P41: 257097 | Q41: 232414 | R41: 318671 | S41: 395524 | T41: 95349 | U41: 2018
B42: 2019 | C42: 7104398 | D42: 1476081 | E42: 435058 | F42: 336092 | G42: 422351 | H42: 221005 | I42: 228766 | J42: 152228 | K42: 58674 | L42: 1806296 | M42: 215965 | N42: 208831 | O42: 259584 | P42: 241523 | Q42: 233271 | R42: 311082 | S42: 405561 | T42: 92030 | U42: 2019
B43: 2020 | C43: 7735491 | D43: 1642977 | E43: 506176 | F43: 364083 | G43: 460304 | H43: 232246 | I43: 243418 | J43: 149696 | K43: 65909 | L43: 1984199 | M43: 217897 | N43: 226441 | O43: 286386 | P43: 257577 | Q43: 248770 | R43: 334679 | S43: 419997 | T43: 94736 | U43: 2020
...

Sheet 4. 시도및성별
A1: ="4. 시도·성별 이동자 수 및 이동률, "&표지!G5 -> 4. 시도·성별 이동자 수 및 이동률, 2025
T2: (단위 : 명, %)
A3: 성별 | B3: 시도 | C3: 총이동자수 | E3: 시도내이동자수 | H3: 시도간이동자수 | J3: 순이동자수 | K3: 총이동률 | M3: 시도내이동률 | P3: 시도간이동률 | R3: 순이동률 | S3: 시도 | T3: 성별
E4: 시군구내 | F4: 시군구간 | M4: 시군구내 | N4: 시군구간
C5: 전입 | D5: 전출 | F5: 전입 | G5: 전출 | H5: 전입 | I5: 전출 | K5: 전입 | L5: 전출 | N5: 전입 | O5: 전출 | P5: 전입 | Q5: 전출
A6: 남녀전체 | T6: 남녀전체
B7: 전국 | C7: 6117784 | D7: 6117784 | E7: 2095832 | F7: 1836039 | G7: 1836039 | H7: 2185913 | I7: 2185913 | J7: 0 | K7: 12.010032 | L7: 12.010032 | M7: 4.1143997 | N7: 3.6043911 | O7: 3.6043911 | P7: 4.2912408 | Q7: 4.2912408 | R7: 0 | S7: 전국
B8: 서울 | C8: 1244928 | D8: 1271697 | E8: 303656 | F8: 502945 | G8: 502945 | H8: 438327 | I8: 465096 | J8: -26769 | K8: 13.462617 | L8: 13.752096 | M8: 3.2837277 | N8: 5.4388334 | O8: 5.4388334 | P8: 4.7400562 | Q8: 5.0295354 | R8: -0.28947923 | S8: 서울
B9: 부산 | C9: 362416 | D9: 374597 | E9: 98453 | F9: 157725 | G9: 157725 | H9: 106238 | I9: 118419 | J9: -12181 | K9: 11.184117 | L9: 11.560021 | M9: 3.0382485 | N9: 4.8673758 | O9: 4.8673758 | P9: 3.2784927 | Q9: 3.654397 | R9: -0.37590429 | S9: 부산
B10: 대구 | C10: 268468 | D10: 272740 | E10: 79840 | F10: 103716 | G10: 103716 | H10: 84912 | I10: 89184 | J10: -4272 | K10: 11.421983 | L10: 11.603735 | M10: 3.3967964 | N10: 4.4126018 | O10: 4.4126018 | P10: 3.6125848 | Q10: 3.7943373 | R10: -0.18175243 | S10: 대구
B11: 인천 | C11: 395525 | D11: 363261 | E11: 122469 | F11: 110822 | G11: 110822 | H11: 162234 | I11: 129970 | J11: 32264 | K11: 13.091899 | L11: 12.023959 | M11: 4.0537307 | N11: 3.6682143 | O11: 3.6682143 | P11: 5.3699544 | Q11: 4.3020142 | R11: 1.0679402 | S11: 인천
B12: 광주 | C12: 162873 | D12: 176551 | E12: 52858 | F12: 56288 | G12: 56288 | H12: 53727 | I12: 67405 | J12: -13678 | K12: 11.668077 | L12: 12.647957 | M12: 3.7867003 | N12: 4.0324224 | O12: 4.0324224 | P12: 3.8489547 | Q12: 4.8288345 | R12: -0.9798798 | S12: 광주
B13: 대전 | C13: 207372 | D13: 204548 | E13: 58381 | F13: 68979 | G13: 68979 | H13: 80012 | I13: 77188 | J13: 2824 | K13: 14.452823 | L13: 14.256004 | M13: 4.0688728 | N13: 4.807502 | O13: 4.807502 | P13: 5.5764486 | Q13: 5.3796295 | R13: 0.19681911 | S13: 대전
B14: 울산 | C14: 114205 | D14: 119679 | E14: 35920 | F14: 37226 | G14: 37226 | H14: 41059 | I14: 46533 | J14: -5474 | K14: 10.459248 | L14: 10.960574 | M14: 3.289665 | N14: 3.4092725 | O14: 3.4092725 | P14: 3.7603105 | Q14: 4.2616364 | R14: -0.50132589 | S14: 울산
B15: 세종 | C15: 54355 | D15: 54402 | E15: 21007 | F15: 0 | G15: 0 | H15: 33348 | I15: 33395 | J15: -47 | K15: 13.918461 | L15: 13.930496 | M15: 5.379176 | N15: 0 | O15: 0 | P15: 8.539285 | Q15: 8.5513201 | R15: -0.012035 | S15: 세종
B16: 경기 | C16: 1628873 | D16: 1595903 | E16: 595484 | F16: 491577 | G16: 491577 | H16: 541812 | I16: 508842 | J16: 32970 | K16: 11.934556 | L16: 11.692989 | M16: 4.3630396 | N16: 3.6017255 | O16: 3.6017255 | P16: 3.9697913 | Q16: 3.7282241 | R16: 0.24156722 | S16: 경기
B17: 강원 | C17: 182825 | D17: 184212 | E17: 83411 | F17: 30259 | G17: 30259 | H17: 69155 | I17: 70542 | J17: -1387 | K17: 12.124864 | L17: 12.216849 | M17: 5.5317763 | N17: 2.0067619 | O17: 2.0067619 | P17: 4.5863254 | Q17: 4.6783106 | R17: -0.091985155 | S17: 강원
B18: 충북 | C18: 199201 | D18: 188412 | E18: 92057 | F18: 25389 | G18: 25389 | H18: 81755 | I18: 70966 | J18: 10789 | K18: 12.533749 | L18: 11.854904 | M18: 5.7922365 | N18: 1.5974787 | O18: 1.5974787 | P18: 5.1440336 | Q18: 4.4651885 | R18: 0.67884506 | S18: 충북
... B24: 제주 | C24: 77588 | D24: 81861 | E24: 41235 | F24: 8017 | G24: 8017 | H24: 28336 | I24: 32609 | J24: -4273 | K24: 11.68817 | L24: 12.331872 | M24: 6.211807 | N24: 1.2077133 | O24: 1.2077133 | P24: 4.2686495 | Q24: 4.9123515 | R24: -0.64370199 | S24: 제주
A25: 남자 | B25: 전국 | C25: 3139371 | D25: 3139371 | E25: 1051628 | F25: 931268 | G25: 931268 | H25: 1156475 | I25: 1156475 | J25: 0 | K25: 12.389237 | L25: 12.389237 | M25: 4.1501525 | N25: 3.6751629 | O25: 3.6751629 | P25: 4.5639215 | Q25: 4.5639215 | R25: 0 | S25: 전국 | T25: 남자
B26: 서울 | C26: 605668 | D26: 623745 | E26: 146528 | F26: 241649 | G26: 241649 | H26: 217491 | I26: 235568 | J26: -18077 | K26: 13.585998 | L26: 13.991491 | M26: 3.2868322 | N26: 5.4205321 | O26: 5.4205321 | P26: 4.8786336 | Q26: 5.2841266 | R26: -0.40549292 | S26: 서울
B27: 부산 | C27: 181790 | D27: 188688 | E27: 47692 | F27: 77731 | G27: 77731 | H27: 56367 | I27: 63265 | J27: -6898 | K27: 11.539852 | L27: 11.97773 | M27: 3.0274417 | N27: 4.9342881 | O27: 4.9342881 | P27: 3.5781222 | Q27: 4.0160005 | R27: -0.43787832 | S27: 부산
B28: 대구 | C28: 135174 | D28: 138485 | E28: 39138 | F28: 51366 | G28: 51366 | H28: 44670 | I28: 47981 | J28: -3311 | K28: 11.740305 | L28: 12.027876 | M28: 3.3992637 | N28: 4.4613056 | O28: 4.4613056 | P28: 3.879736 | Q28: 4.1673072 | R28: -0.28757121 | S28: 대구
B29: 인천 | C29: 203539 | D29: 187129 | E29: 61065 | F29: 56617 | G29: 56617 | H29: 85857 | I29: 69447 | J29: 16410 | K29: 13.499689 | L29: 12.411299 | M29: 4.0501257 | N29: 3.7551128 | O29: 3.7551128 | P29: 5.6944508 | Q29: 4.6060604 | R29: 1.0883904 | S29: 인천
B30: 광주 | C30: 82558 | D30: 89372 | E30: 26128 | F30: 28029 | G30: 28029 | H30: 28401 | I30: 35215 | J30: -6814 | K30: 11.996893 | L30: 12.987068 | M30: 3.7967832 | N30: 4.0730265 | O30: 4.0730265 | P30: 4.1270835 | Q30: 5.1172581 | R30: -0.99017455 | S30: 광주
B31: 대전 | C31: 106596 | D31: 104998 | E31: 28955 | F31: 34865 | G31: 34865 | H31: 42776 | I31: 41178 | J31: 1598 | K31: 14.92099 | L31: 14.697307 | M31: 4.0530345 | N31: 4.8802987 | O31: 4.8802987 | P31: 5.9876568 | Q31: 5.7639736 | R31: 0.22368327 | S31: 대전
B32: 울산 | C32: 62934 | D32: 64261 | E32: 18690 | F32: 19483 | G32: 19483 | H32: 24761 | I32: 26088 | J32: -1327 | K32: 11.200841 | L32: 11.437018 | M32: 3.3264011 | N32: 3.4675373 | O32: 3.4675373 | P32: 4.406903 | Q32: 4.6430793 | R32: -0.23617626 | S32: 울산
B33: 세종 | C33: 27308 | D33: 27258 | E33: 10195 | F33: 0 | G33: 0 | H33: 17113 | I33: 17063 | J33: 50 | K33: 14.053361 | L33: 14.02763 | M33: 5.2465951 | N33: 0 | O33: 0 | P33: 8.8067663 | Q33: 8.7810351 | R33: 0.0257312 | S33: 세종
B34: 경기 | C34: 843579 | D34: 828812 | E34: 300831 | F34: 258700 | G34: 258700 | H34: 284048 | I34: 269281 | J34: 14767 | K34: 12.309986 | L34: 12.094498 | M34: 4.3898977 | N34: 3.7750981 | O34: 3.7750981 | P34: 4.1449906 | Q34: 3.9295021 | R34: 0.2154885 | S34: 경기
B35: 강원 | C35: 96219 | D35: 96328 | E35: 42030 | F35: 16310 | G35: 16310 | H35: 37879 | I35: 37988 | J35: -109 | K35: 12.697133 | L35: 12.711517 | M35: 5.546311 | N35: 2.1522801 | O35: 2.1522801 | P35: 4.9985418 | Q35: 5.0129256 | R35: -0.014384 | S35: 강원
B36: 충북 | C36: 105916 | D36: 99200 | E36: 47035 | F36: 13390 | G36: 13390 | H36: 45491 | I36: 38775 | J36: 6716 | K36: 13.092431 | L36: 12.262257 | M36: 5.8140649 | N36: 1.6551574 | O36: 1.6551574 | P36: 5.6232088 | Q36: 4.7930342 | R36: 0.83017455 | S36: 충북
B37: 충남 | C37: 135564 | D37: 130126 | E37: 48629 | F37: 22922 | G37: 22922 | H37: 64013 | I37: 58575 | J37: 5438 | K37: 12.408865 | L37: 11.911097 | M37: 4.4512608 | N37: 2.0981677 | O37: 2.0981677 | P37: 5.8594369 | Q37: 5.3616689 | R37: 0.49776792 | S37: 충남
... B42: 제주 | C42: 39485 | D42: 41763 | E42: 20742 | F42: 4098 | G42: 4098 | H42: 14645 | I42: 16923 | J42: -2278 | K42: 11.902124 | L42: 12.588791 | M42: 6.2523455 | N42: 1.2352768 | O42: 1.2352768 | P42: 4.414502 | Q42: 5.1011688 | R42: -0.68666682 | S42: 제주
A43: 여자 | B43: 전국 | C43: 2978413 | D43: 2978413 | E43: 1044204 | F43: 904771 | G43: 904771 | H43: 1029438 | I43: 1029438 | J43: 0 | K43: 11.634677 | L43: 11.634677 | M43: 4.0790099 | N43: 3.534338 | O43: 3.534338 | P43: 4.021329 | Q43: 4.021329 | R43: 0 | S43: 전국 | T43: 여자
B44: 서울 | C44: 639260 | D44: 647952 | E44: 157128 | F44: 261296 | G44: 261296 | H44: 220836 | I44: 229528 | J44: -8692 | K44: 13.34777 | L44: 13.529259 | M44: 3.2808378 | N44: 5.4558691 | O44: 5.4558691 | P44: 4.6110629 | Q44: 4.7925522 | R44: -0.18148924 | S44: 서울
B45: 부산 | C45: 180626 | D45: 185909 | E45: 50761 | F45: 79994 | G45: 79994 | H45: 49871 | I45: 55154 | J45: -5283 | K45: 10.847568 | L45: 11.164841 | M45: 3.0484725 | N45: 4.8040722 | O45: 4.8040722 | P45: 2.9950232 | Q45: 3.3122959 | R45: -0.31727272 | S45: 부산
B46: 대구 | C46: 133294 | D46: 134255 | E46: 40702 | F46: 52350 | G46: 52350 | H46: 40242 | I46: 41203 | J46: -961 | K46: 11.116328 | L46: 11.196473 | M46: 3.3944272 | N46: 4.3658362 | O46: 4.3658362 | P46: 3.3560646 | Q46: 3.4362092 | R46: -0.080144577 | S46: 대구
B47: 인천 | C47: 191986 | D47: 176132 | E47: 61404 | F47: 54205 | G47: 54205 | H47: 76377 | I47: 60523 | J47: 15854 | K47: 12.68564 | L47: 11.638073 | M47: 4.0573221 | N47: 3.581642 | O47: 3.581642 | P47: 5.046676 | Q47: 3.9991093 | R47: 1.0475667 | S47: 인천
B48: 광주 | C48: 80315 | D48: 87179 | E48: 26730 | F48: 28259 | G48: 28259 | H48: 25326 | I48: 32190 | J48: -6864 | K48: 11.34835 | L48: 12.31822 | M48: 3.7768961 | N48: 3.9929408 | O48: 3.9929408 | P48: 3.5785137 | Q48: 4.5483833 | R48: -0.96986961 | S48: 광주
B49: 대전 | C49: 100776 | D49: 99550 | E49: 29426 | F49: 34114 | G49: 34114 | H49: 37236 | I49: 36010 | J49: 1226 | K49: 13.988565 | L49: 13.818386 | M49: 4.0845788 | N49: 4.735313 | O49: 4.735313 | P49: 5.1686731 | Q49: 4.9984939 | R49: 0.17017922 | S49: 대전
...

Sheet 5. 시도 및 연령별 순이동
A1: ="5. 시도 및 성·연령별 순이동자 수, "&표지!G5 -> 5. 시도 및 성·연령별 순이동자 수, 2025
U2: (단위 : 명)
A3: 성별 | B3: 시도 연령 | C3: 서울 | D3: 부산 | E3: 대구 | F3: 인천 | G3: 광주 | H3: 대전 | I3: 울산 | J3: 세종 | K3: 경기 | L3: 강원 | M3: 충북 | N3: 충남 | O3: 전북 | P3: 전남 | Q3: 경북 | R3: 경남 | S3: 제주 | T3: 시도 연령 | U3: 성별
A4: 남녀전체 | U4: 남녀전체
B5: 계 | C5: -26769 | D5: -12181 | E5: -4272 | F5: 32264 | G5: -13678 | H5: 2824 | I5: -5474 | J5: -47 | K5: 32970 | L5: -1387 | M5: 10789 | N5: 8266 | O5: -3575 | P5: 1334 | Q5: -9214 | R5: -7577 | S5: -4273 | T5: 계
B6: 0- 4세 | C6: -4984 | D6: 265 | E6: 999 | F6: 2431 | G6: 139 | H6: -44 | I6: -166 | J6: 143 | K6: 2173 | L6: -274 | M6: 330 | N6: -7 | O6: 65 | P6: -260 | Q6: -896 | R6: 55 | S6: 31 | T6: 0- 4세
B7: 5- 9세 | C7: 590 | D7: 141 | E7: 673 | F7: 1328 | G7: -67 | H7: 182 | I7: -306 | J7: 63 | K7: -1378 | L7: -130 | M7: 147 | N7: 52 | O7: -20 | P7: -116 | Q7: -778 | R7: -373 | S7: -8 | T7: 5- 9세
B8: 10-14세 | C8: 645 | D8: -96 | E8: 344 | F8: 1125 | G8: -268 | H8: 232 | I8: -214 | J8: 0 | K8: -1072 | L8: -240 | M8: 111 | N8: 372 | O8: -19 | P8: -48 | Q8: -416 | R8: -219 | S8: -237 | T8: 10-14세
B9: 15-19세 | C9: 8367 | D9: 556 | E9: 20 | F9: 701 | G9: -721 | H9: 1135 | I9: -1255 | J9: -523 | K9: -1378 | L9: -100 | M9: 103 | N9: -600 | O9: -572 | P9: -1032 | Q9: -915 | R9: -2956 | S9: -830 | T9: 15-19세
B10: 20-24세 | C10: 25664 | D10: 927 | E10: -1659 | F10: 1572 | G10: -2064 | H10: 2042 | I10: -1740 | J10: -479 | K10: 2486 | L10: -2293 | M10: -546 | N10: -2343 | O10: -2849 | P10: -3790 | Q10: -5842 | R10: -7496 | S10: -1590 | T10: 20-24세
B11: 25-29세 | C11: 10273 | D11: -5437 | E11: -3225 | F11: 3432 | G11: -3163 | H11: 206 | I11: 586 | J11: 773 | K11: 4953 | L11: -1472 | M11: 996 | N11: 1210 | O11: -2590 | P11: -1304 | Q11: -2997 | R11: -1633 | S11: -608 | T11: 25-29세
B12: 30-34세 | C12: -10861 | D12: -2236 | E12: -444 | F12: 3830 | G12: -1744 | H12: 320 | I12: 245 | J12: 847 | K12: 9716 | L12: -267 | M12: 1125 | N12: 853 | O12: -597 | P12: 339 | Q12: -1225 | R12: 266 | S12: -167 | T12: 30-34세
B13: 35-39세 | C13: -7869 | D13: -482 | E13: 655 | F13: 3638 | G13: -1063 | H13: -135 | I13: -203 | J13: 104 | K13: 3898 | L13: -145 | M13: 968 | N13: 572 | O13: -38 | P13: 558 | Q13: -695 | R13: 318 | S13: -81 | T13: 35-39세
B14: 40-44세 | C14: -4412 | D14: -323 | E14: 534 | F14: 2902 | G14: -702 | H14: 245 | I14: -359 | J14: -67 | K14: -221 | L14: 27 | M14: 797 | N14: 808 | O14: 284 | P14: 726 | Q14: -313 | R14: 49 | S14: 25 | T14: 40-44세
B15: 45-49세 | C15: -4079 | D15: -670 | E15: 123 | F15: 2170 | G15: -617 | H15: 65 | I15: -156 | J15: -253 | K15: -151 | L15: 242 | M15: 1083 | N15: 844 | O15: 247 | P15: 836 | Q15: 107 | R15: 376 | S15: -167 | T15: 45-49세
B16: 50-54세 | C16: -6493 | D16: -709 | E16: -417 | F16: 2073 | G16: -919 | H16: -346 | I16: -191 | J16: -289 | K16: 838 | L16: 644 | M16: 1312 | N16: 1132 | O16: 546 | P16: 1467 | Q16: 811 | R16: 669 | S16: -128 | T16: 50-54세
... B22: 80세이상 | C22: -4331 | D22: -313 | E22: 81 | F22: 1480 | G22: 270 | H22: 218 | I22: 274 | J22: -36 | K22: 4648 | L22: -242 | M22: 89 | N22: -147 | O22: -388 | P22: -1074 | Q22: -435 | R22: -33 | S22: -61 | T22: 80세이상
A23: 남자 | B23: 계 | C23: -18077 | D23: -6898 | E23: -3311 | F23: 16410 | G23: -6814 | H23: 1598 | I23: -1327 | J23: 50 | K23: 14767 | L23: -109 | M23: 6716 | N23: 5438 | O23: -1500 | P23: 1782 | Q23: -3981 | R23: -2466 | S23: -2278 | T23: 계 | U23: 남자
B24: 0- 4세 | C24: -2577 | D24: 129 | E24: 520 | F24: 1243 | G24: 85 | H24: -53 | I24: -93 | J24: 101 | K24: 1136 | L24: -127 | M24: 166 | N24: -60 | O24: 45 | P24: -132 | Q24: -474 | R24: 69 | S24: 22 | T24: 0- 4세
B25: 5- 9세 | C25: 335 | D25: 68 | E25: 342 | F25: 690 | G25: -33 | H25: 104 | I25: -140 | J25: 39 | K25: -697 | L25: -110 | M25: 81 | N25: -9 | O25: -12 | P25: -6 | Q25: -435 | R25: -184 | S25: -33 | T25: 5- 9세
B26: 10-14세 | C26: 316 | D26: -33 | E26: 172 | F26: 575 | G26: -137 | H26: 120 | I26: -93 | J26: -1 | K26: -733 | L26: -93 | M26: 110 | N26: 197 | O26: -55 | P26: 0 | Q26: -188 | R26: -29 | S26: -128 | T26: 10-14세
B27: 15-19세 | C27: 2182 | D27: -193 | E27: -126 | F27: 385 | G27: -382 | H27: 207 | I27: -357 | J27: -181 | K27: -274 | L27: 76 | M27: 234 | N27: -256 | O27: -116 | P27: -150 | Q27: -51 | R27: -663 | S27: -335 | T27: 15-19세
B28: 20-24세 | C28: 9021 | D28: 827 | E28: -878 | F28: 571 | G28: -864 | H28: 1540 | I28: -753 | J28: -231 | K28: 1831 | L28: -571 | M28: 163 | N28: -667 | O28: -1227 | P28: -1723 | Q28: -2501 | R28: -3623 | S28: -915 | T28: 20-24세
B29: 25-29세 | C29: 6095 | D29: -3239 | E29: -1965 | F29: 2090 | G29: -1779 | H29: 228 | I29: 784 | J29: 319 | K29: 3467 | L29: -1124 | M29: 690 | N29: 774 | O29: -1650 | P29: -961 | Q29: -2067 | R29: -1265 | S29: -397 | T29: 25-29세
B30: 30-34세 | C30: -4699 | D30: -1025 | E30: -329 | F30: 2169 | G30: -765 | H30: 147 | I30: 247 | J30: 527 | K30: 4369 | L30: -309 | M30: 649 | N30: 412 | O30: -431 | P30: -49 | Q30: -893 | R30: 132 | S30: -152 | T30: 30-34세
B31: 35-39세 | C31: -4245 | D31: -254 | E31: 242 | F31: 1939 | G31: -594 | H31: -50 | I31: -13 | J31: 40 | K31: 1958 | L31: -58 | M31: 551 | N31: 252 | O31: -26 | P31: 383 | Q31: -341 | R31: 272 | S31: -56 | T31: 35-39세
B32: 40-44세 | C32: -2735 | D32: -231 | E32: 218 | F32: 1674 | G32: -431 | H32: 71 | I32: -161 | J32: -36 | K32: -43 | L32: -8 | M32: 488 | N32: 491 | O32: 143 | P32: 483 | Q32: -124 | R32: 165 | S32: 36 | T32: 40-44세
B33: 45-49세 | C33: -2189 | D33: -341 | E33: -12 | F33: 1202 | G33: -256 | H33: 17 | I33: 40 | J33: -120 | K33: -631 | L33: 165 | M33: 630 | N33: 556 | O33: 137 | P33: 476 | Q33: 89 | R33: 285 | S33: -48 | T33: 45-49세
B34: 50-54세 | C34: -3254 | D34: -435 | E34: -235 | F34: 1063 | G34: -370 | H34: -83 | I34: 101 | J34: -198 | K34: 1 | L34: 323 | M34: 668 | N34: 599 | O34: 300 | P34: 730 | Q34: 443 | R34: 444 | S34: -97 | T34: 50-54세
B35: 55-59세 | C35: -4050 | D35: -513 | E35: -417 | F35: 786 | G35: -525 | H35: -254 | I35: -126 | J35: -86 | K35: 309 | L35: 477 | M35: 756 | N35: 824 | O35: 411 | P35: 979 | Q35: 824 | R35: 612 | S35: -7 | T35: 55-59세
